<?xml version="1.0" encoding="utf-8"?>
<!-- =================================================================================== -->         
<!--   This URDF contains a robot model with Velocity Controllers and various sensors -->
<!--               THis file contains planar_move plugin that moves the robot         -->
<!-- =================================================================================== -->
<robot name="prototype_one" xmlns:xacro="http://www.ros.org/wiki/xacro">
	

	<xacro:property name="robot_name" value="prototype_one" />
    
	<!-- chassis setting -->
    	<xacro:property name="robot_chassis_mass" value="15"/>
	<xacro:property name="robot_chassis_length" value="0.2"/>
	<xacro:property name="robot_chassis_radius" value="0.25"/>
	<xacro:property name="robot_caster_wheel_radius" value="0.05"/>
	<xacro:property name="robot_caster_wheel_radius_collision" value="0.0499"/>

	<xacro:property name="robot_wheel_mass" value="5"/>
	<xacro:property name="robot_wheel_length" value="0.05"/>
	<xacro:property name="robot_wheel_radius" value="0.1"/>

	<xacro:property name="camera_mass" value="0.1"/>
	<xacro:property name="hokoyu_mass" value="1e-5"/>
	
	
	<link name="prototype_one_base_footprint">
	    <visual>
	      <origin rpy="0 0 0" xyz="0 0 0"/>
	      <geometry>
		<box size="0.001 0.001 0.001"/>
	      </geometry>
	    </visual>
	</link>
	<joint name="prototype_one_base_footprint_joint" type="fixed">
	    <origin rpy="0 0 0" xyz="0 0 0.127"/>
	    <!-- ${wheel_radius} property must be defined inside wheel description -->
	    <parent link="prototype_one_base_footprint"/>
	    <child link="prototype_one_base_link"/>
	</joint>
	
	<!-- base link -->
	<link name="prototype_one_base_link">
	<pose>0 0 0.1 0 0 0</pose>

		<inertial>
			<mass value="15"/>
      		<origin xyz="0.0 0 0" rpy=" 0 0 0"/>

      		<inertia 
      			ixx="0.147116667" ixy="0" ixz="0"
      			iyy="0.334951167" iyz="0"
      			izz="0.3978345"
      		/>
		</inertial>

		<collision name="collision">
			<origin xyz="0 0 0.05" rpy=" 0 0 0"/>
			<geometry>
				<box size="0.6 0.4 0.2"/>
			</geometry>
		</collision>

		<visual name="chassis_visual">
			<origin xyz="0 0 0.05" rpy=" 0 0 0"/>
			<geometry>
				<box size="0.6 0.4 0.2"/>
			</geometry>

		</visual>

	</link>
	
	<!-- Right Wheel Back -->
	<link name="prototype_one_right_wheel_back">
		<inertial>
			<mass value="5"/>
			<origin xyz="0 0 0" rpy="0 1.5707 1.5707"/>
			<inertia
				ixx="0.1" ixy="0.0" ixz="0.0"
				iyy="0.1" iyz="0.0"
				izz="0.1"
			/>
		</inertial>

		<visual>
			<origin xyz="0 0 0" rpy="0 1.5707 1.5707"/>
			<geometry>
				<cylinder radius="0.1" length="0.05"/>
			</geometry>
		</visual>

		<collision>
			<origin xyz="0 0 0" rpy="0 1.5707 1.5707"/>
			<geometry>
				<cylinder radius="0.1" length="0.05"/>
			</geometry>
		</collision>

	</link>
	
	<!-- Right Wheel Front-->
	<link name="prototype_one_right_wheel_front">
		<inertial>
			<mass value="5"/>
			<origin xyz="0 0 0" rpy="0 1.5707 1.5707"/>
			<inertia
				ixx="0.1" ixy="0.0" ixz="0.0"
				iyy="0.1" iyz="0.0"
				izz="0.1"
			/>
		</inertial>

		<visual>
			<origin xyz="0 0 0" rpy="0 1.5707 1.5707"/>
			<geometry>
				<cylinder radius="0.1" length="0.05"/>
			</geometry>
		</visual>

		<collision>
			<origin xyz="0 0 0" rpy="0 1.5707 1.5707"/>
			<geometry>
				<cylinder radius="0.1" length="0.05"/>
			</geometry>
		</collision>

	</link>
	
	<!-- Left wheel Back-->
	<link name="prototype_one_left_wheel_back">
		<inertial>
			<mass value="5"/>
			<origin xyz="0 0 0" rpy="0 1.5707 1.5707"/>
			<inertia
				ixx="0.1" ixy="0.0" ixz="0.0"
				iyy="0.1" iyz="0.0"
				izz="0.1"
			/>
		</inertial>

		<visual>
			<origin xyz="0 0 0" rpy="0 1.5707 1.5707"/>
			<geometry>
				<cylinder radius="0.1" length="0.05"/>
			</geometry>
		</visual>

		<collision>
			<origin xyz="0 0 0" rpy="0 1.5707 1.5707"/>
			<geometry>
				<cylinder radius="0.1" length="0.05"/>
			</geometry>
		</collision>

	</link>
	
	
	<!-- Left wheel Front-->
	<link name="proto_type_one_left_wheel_front">
		<inertial>
			<mass value="5"/>
			<origin xyz="0 0 0" rpy="0 1.5707 1.5707"/>
			<inertia
				ixx="0.1" ixy="0.0" ixz="0.0"
				iyy="0.1" iyz="0.0"
				izz="0.1"
			/>
		</inertial>

		<visual>
			<origin xyz="0 0 0" rpy="0 1.5707 1.5707"/>
			<geometry>
				<cylinder radius="0.1" length="0.05"/>
			</geometry>
		</visual>

		<collision>
			<origin xyz="0 0 0" rpy="0 1.5707 1.5707"/>
			<geometry>
				<cylinder radius="0.1" length="0.05"/>
			</geometry>
		</collision>

	</link>
	
	<!-- Camera -->
	<link name="camera">
		<inertial>
			<mass value="0.1"/>
			<origin xyz="0 0 0" rpy="0 0 0"/>
			<inertia
		        ixx="1e-6" ixy="0.0" ixz="0.0"
		        iyy="1e-6" iyz="0.0"
		        izz="1e-6"
		      />
		</inertial>

		<visual>
			<origin xyz="0 0 0" rpy="0 0 0"/>
			<geometry>
				<box size="0.05 0.05 0.05"/>
			</geometry>
		</visual>

		<collision>
			<origin xyz="0 0 0" rpy="0 0 0"/>
			<geometry>
				<box size="0.05 0.05 0.05"/>
			</geometry>
		</collision>
	</link>

	<!-- Hokuyo Lidar -->
	<link name="hokuyo">
		<inertial>
			<mass value="0.00001"/>
			<origin xyz="0 0 0" rpy="0 0 0"/>

			<inertia
		        ixx="1e-6" ixy="0.0" ixz="0.0"
		        iyy="1e-6" iyz="0.0"
		        izz="1e-6"
		      />
		</inertial>

		<visual>
			<origin xyz="0 0 0" rpy="0 0 0"/>
			<geometry>
				<box size="0.1 0.1 0.1"/>
			</geometry>
		</visual>

		<collision>
			<origin xyz="0 0 0" rpy="0 0 0"/>
			<geometry>
				<box size="0.1 0.1 0.1"/>
			</geometry>
		</collision>
	</link>
	
	<!-- Define Joints -->

	<!-- Right Wheel Joint Back-->
	<joint type="continuous" name="prototype_one_right_wheel_hinge_back">
	    <origin xyz="-0.2 -0.2 0" rpy="0 0 0" />
	    <parent link="prototype_one_base_link"/>
	    <child link="prototype_one_right_wheel_back" />
	    <axis xyz="0 1 0" rpy="0 0 0" />
	    <limit effort="10000" velocity="1000" />
	    <dynamics damping="1.0" friction="1.0" />
	</joint>
	
	<!-- Right Wheel Joint Front-->
	<joint type="continuous" name="prototype_one_right_wheel_hinge_front">
	    <origin xyz="0.2 -0.2 0" rpy="0 0 0" />
	    <parent link="prototype_one_base_link"/>
	    <child link="prototype_one_right_wheel_front" />
	    <axis xyz="0 1 0" rpy="0 0 0" />
	    <limit effort="10000" velocity="1000" />
	    <dynamics damping="1.0" friction="1.0" />
	</joint>
	
	<!-- Left Wheel Joint Back-->
	<joint type="continuous" name="prototype_one_left_wheel_hinge_back">
	    <origin xyz="-0.2 0.2 0" rpy="0 0 0" />
	    <parent link="prototype_one_base_link"/>
	    <child link="prototype_one_left_wheel_back" />
	    <axis xyz="0 1 0" rpy="0 0 0" />
	    <limit effort="10000" velocity="1000" />
	    <dynamics damping="1.0" friction="1.0" />
	</joint>

	<!-- Left Wheel Joint Front-->
	<joint type="continuous" name="prototype_one_left_wheel_hinge_front">
	    <origin xyz="0.2 0.2 0" rpy="0 0 0" />
	    <parent link="prototype_one_base_link"/>
	    <child link="prototype_one_left_wheel_front" />
	    <axis xyz="0 1 0" rpy="0 0 0" />
	    <limit effort="10000" velocity="1000" />
	    <dynamics damping="1.0" friction="1.0" />
	</joint>

	<!-- Camera Joint -->
	<joint name="camera_joint" type="fixed">
		<origin xyz="0.31 0 0" rpy="0 0 0" />
		<parent link="prototype_one_base_link"/>
		<child link="camera" />
		<axis xyz="0 1 0"/>
	</joint>

	<!-- Hokoyu Joint -->
	<joint name="hokuyo_joint" type="fixed">
	    <origin xyz="0.2 0 0.2" rpy="0 0 0" />
	    <parent link="prototype_one_base_link"/>
	    <child link="hokuyo" />  
	    <axis xyz="0 1 0"/> 
	</joint>

	<joint name="prototype_one_base_link_joint" type="fixed">
		<origin xyz="0 0 0" rpy="0 0 0" />
		<parent link="prototype_one_base_footprint"/>
		<child link="prototype_one_base_link" />
	</joint>



	
</robot>
	
